2021-11-18 15:55:09,699 - D:\Audit\logis_fir\tools.py[line:37] - ERROR: 错误:Traceback (most recent call last):
  File "D:\Audit\logis_fir\tools.py", line 29, in executeSql
    cur.execute(sql)
sqlite3.OperationalError: near "WHERE": syntax error

2021-11-18 15:55:16,026 - D:\Audit\logis_fir\tools.py[line:37] - ERROR: 错误:Traceback (most recent call last):
  File "D:\Audit\logis_fir\tools.py", line 29, in executeSql
    cur.execute(sql)
sqlite3.OperationalError: near "WHERE": syntax error

2021-11-18 15:55:16,026 - D:\Audit\logis_fir\tools.py[line:37] - ERROR: 错误:Traceback (most recent call last):
  File "D:\Audit\logis_fir\tools.py", line 29, in executeSql
    cur.execute(sql)
sqlite3.OperationalError: near "WHERE": syntax error

2021-11-18 15:55:35,811 - D:\Audit\logis_fir\tools.py[line:37] - ERROR: 错误:Traceback (most recent call last):
  File "D:\Audit\logis_fir\tools.py", line 29, in executeSql
    cur.execute(sql)
sqlite3.OperationalError: near "WHERE": syntax error

2021-11-18 15:56:05,715 - D:\Audit\logis_fir\tools.py[line:37] - ERROR: 错误:Traceback (most recent call last):
  File "D:\Audit\logis_fir\tools.py", line 29, in executeSql
    cur.execute(sql)
sqlite3.OperationalError: near "bwprocess": syntax error

2021-11-18 16:06:01,066 - D:\Audit\logis_fir\tools.py[line:37] - ERROR: 错误:Traceback (most recent call last):
  File "D:\Audit\logis_fir\tools.py", line 29, in executeSql
    cur.execute(sql)
sqlite3.OperationalError: no such column: 测试

2021-11-18 17:21:17,808 - D:\Audit\logis_fir\tools.py[line:37] - ERROR: 错误:Traceback (most recent call last):
  File "D:\Audit\logis_fir\tools.py", line 29, in executeSql
    cur.execute(sql)
sqlite3.OperationalError: no such column: None

