2021-12-12 20:43:56,228 - E:\GitHub repository\Audit\logis_fir\tools.py[line:37] - ERROR: 错误:Traceback (most recent call last):
  File "E:\GitHub repository\Audit\logis_fir\tools.py", line 29, in executeSql
    cur.execute(sql)
sqlite3.OperationalError: no such column: 问题金额统计

2021-12-12 20:46:17,585 - E:\GitHub repository\Audit\logis_fir\tools.py[line:37] - ERROR: 错误:Traceback (most recent call last):
  File "E:\GitHub repository\Audit\logis_fir\tools.py", line 29, in executeSql
    cur.execute(sql)
sqlite3.OperationalError: no such column: 问题数量统计

2021-12-12 20:46:17,585 - E:\GitHub repository\Audit\logis_fir\tools.py[line:37] - ERROR: 错误:Traceback (most recent call last):
  File "E:\GitHub repository\Audit\logis_fir\tools.py", line 29, in executeSql
    cur.execute(sql)
sqlite3.OperationalError: no such column: 问题数量统计

2021-12-12 20:55:16,516 - E:\GitHub repository\Audit\logis_fir\tools.py[line:37] - ERROR: 错误:Traceback (most recent call last):
  File "E:\GitHub repository\Audit\logis_fir\tools.py", line 29, in executeSql
    cur.execute(sql)
sqlite3.OperationalError: misuse of aggregate function count()

2021-12-16 23:26:50,311 - E:\GitHub repository\Audit\logis_fir\call_zgdetail.py[line:1008] - ERROR: 错误:Traceback (most recent call last):
  File "E:\GitHub repository\Audit\logis_fir\call_zgdetail.py", line 986, in importExcelProblemZg
    send_file_name = data[0][0]
IndexError: list index out of range

2021-12-16 23:26:54,448 - E:\GitHub repository\Audit\logis_fir\call_zgdetail.py[line:1008] - ERROR: 错误:Traceback (most recent call last):
  File "E:\GitHub repository\Audit\logis_fir\call_zgdetail.py", line 986, in importExcelProblemZg
    send_file_name = data[0][0]
IndexError: list index out of range

2021-12-16 23:26:54,448 - E:\GitHub repository\Audit\logis_fir\call_zgdetail.py[line:1008] - ERROR: 错误:Traceback (most recent call last):
  File "E:\GitHub repository\Audit\logis_fir\call_zgdetail.py", line 986, in importExcelProblemZg
    send_file_name = data[0][0]
IndexError: list index out of range

2021-12-16 23:26:55,877 - E:\GitHub repository\Audit\logis_fir\call_zgdetail.py[line:1008] - ERROR: 错误:Traceback (most recent call last):
  File "E:\GitHub repository\Audit\logis_fir\call_zgdetail.py", line 986, in importExcelProblemZg
    send_file_name = data[0][0]
IndexError: list index out of range

2021-12-16 23:26:55,877 - E:\GitHub repository\Audit\logis_fir\call_zgdetail.py[line:1008] - ERROR: 错误:Traceback (most recent call last):
  File "E:\GitHub repository\Audit\logis_fir\call_zgdetail.py", line 986, in importExcelProblemZg
    send_file_name = data[0][0]
IndexError: list index out of range

2021-12-16 23:26:55,877 - E:\GitHub repository\Audit\logis_fir\call_zgdetail.py[line:1008] - ERROR: 错误:Traceback (most recent call last):
  File "E:\GitHub repository\Audit\logis_fir\call_zgdetail.py", line 986, in importExcelProblemZg
    send_file_name = data[0][0]
IndexError: list index out of range

2021-12-16 23:50:48,757 - E:\GitHub repository\Audit\logis_fir\call_zgdetail.py[line:1008] - ERROR: 错误:Traceback (most recent call last):
  File "E:\GitHub repository\Audit\logis_fir\call_zgdetail.py", line 986, in importExcelProblemZg
    send_file_name = data[0][0]
IndexError: list index out of range

2021-12-16 23:50:55,394 - E:\GitHub repository\Audit\logis_fir\call_zgdetail.py[line:1008] - ERROR: 错误:Traceback (most recent call last):
  File "E:\GitHub repository\Audit\logis_fir\call_zgdetail.py", line 986, in importExcelProblemZg
    send_file_name = data[0][0]
IndexError: list index out of range

2021-12-16 23:50:55,394 - E:\GitHub repository\Audit\logis_fir\call_zgdetail.py[line:1008] - ERROR: 错误:Traceback (most recent call last):
  File "E:\GitHub repository\Audit\logis_fir\call_zgdetail.py", line 986, in importExcelProblemZg
    send_file_name = data[0][0]
IndexError: list index out of range

2021-12-17 00:38:30,685 - E:\GitHub repository\Audit\logis_fir\tools.py[line:37] - ERROR: 错误:Traceback (most recent call last):
  File "E:\GitHub repository\Audit\logis_fir\tools.py", line 29, in executeSql
    cur.execute(sql)
sqlite3.OperationalError: near "select": syntax error

2021-12-17 00:39:13,118 - E:\GitHub repository\Audit\logis_fir\tools.py[line:37] - ERROR: 错误:Traceback (most recent call last):
  File "E:\GitHub repository\Audit\logis_fir\tools.py", line 29, in executeSql
    cur.execute(sql)
sqlite3.OperationalError: near "select": syntax error

2021-12-17 01:35:42,050 - E:\GitHub repository\Audit\logis_fir\tools.py[line:37] - ERROR: 错误:Traceback (most recent call last):
  File "E:\GitHub repository\Audit\logis_fir\tools.py", line 29, in executeSql
    cur.execute(sql)
sqlite3.OperationalError: near ")": syntax error

2021-12-17 01:36:59,083 - E:\GitHub repository\Audit\logis_fir\tools.py[line:37] - ERROR: 错误:Traceback (most recent call last):
  File "E:\GitHub repository\Audit\logis_fir\tools.py", line 29, in executeSql
    cur.execute(sql)
sqlite3.OperationalError: no such column: rectification_jz.认定整改状况

